<?xml version="1.0"?>

<robot name="sixDOF">
  
  <!-- *************************************************** -->
  <!-- ******************** Kinematics ******************* -->
  <!-- *************************************************** -->

  <link name="world"/>


  <joint name="base" type="continuous">
    <parent link="world"/>
    <child  link="lbracket"/>
    <origin xyz="0 -.0775 0.07" rpy="0 0 0"/>
    <axis   xyz="0 0 1"/>
  </joint>

  <link name="lbracket"/>

  <joint name="shoulder" type="continuous">
    <parent link="lbracket"/>
    <child  link="bicep"/>
    <origin xyz="0 0 .055" rpy="0 0 0"/>
    <axis   xyz="-1 0 0"/>
  </joint>

  <link name="bicep"/>

  <joint name="elbow" type="continuous">
    <parent link="bicep"/>
    <child  link="forearm"/>
    <origin xyz="0.052 0 .45" rpy="0 0 0"/>
    <axis   xyz="1 0 0 "/>
  </joint>

  <link name="forearm"/>

  <joint name="wrist" type="continuous">
    <parent link="forearm"/>
    <child  link="hand"/>
    <origin xyz="0 0 .465" rpy="0 0 0"/>
    <axis   xyz="-1 0 0"/>
  </joint>

  <link name="hand"/>

  <joint name="head" type="continuous">
    <parent link="hand"/>
    <child  link="camera"/>
    <origin xyz="-.0975 0 -.045" rpy="0 0 0"/>
    <axis   xyz="0 0 -1"/>
  </joint>

  <link name="camera"/>

  <joint name="final" type="fixed">
    <parent link="camera"/>
    <child  link="tip"/>
    <origin xyz=".035 .095 -0.08" rpy="0 0 0"/>
  </joint>

  <link name="tip"/>


  <!-- *************************************************** -->
  <!-- ******************* RVIZ Colors ******************* -->
  <!-- *************************************************** -->

  <material name="white">    <color rgba="1.00 1.00 1.00 1"/>  </material>
  <material name="gray">     <color rgba="0.60 0.60 0.60 1"/>  </material>
  <material name="table">    <color rgba="0.85 0.77 0.77 1"/>  </material>
  <material name="black">    <color rgba="0.00 0.00 0.00 1"/>  </material>

  <material name="red">      <color rgba="1.00 0.00 0.00 1"/>  </material>
  <material name="green">    <color rgba="0.00 1.00 0.00 1"/>  </material>
  <material name="blue">     <color rgba="0.00 0.00 1.00 1"/>  </material>

  <material name="cyan">     <color rgba="0.00 1.00 1.00 1"/>  </material>
  <material name="magenta">  <color rgba="1.00 0.00 1.00 1"/>  </material>
  <material name="yellow">   <color rgba="1.00 1.00 0.00 1"/>  </material>

  <material name="orange">   <color rgba="1.00 0.65 0.00 1"/>  </material>


  <!-- *************************************************** -->
  <!-- ****** Building Blocks (Visual AND Inertial) ****** -->
  <!-- *************************************************** -->

  <!-- *** World-Fixed: Mount 1, Motor 1 *** -->



</robot>
